[2024-04-10T12:45:50.425+0000] {taskinstance.py:1083} INFO - Dependencies all met for <TaskInstance: primeira_dag.task2 manual__2024-04-10T12:45:39.090136+00:00 [queued]>
[2024-04-10T12:45:50.460+0000] {taskinstance.py:1083} INFO - Dependencies all met for <TaskInstance: primeira_dag.task2 manual__2024-04-10T12:45:39.090136+00:00 [queued]>
[2024-04-10T12:45:50.462+0000] {taskinstance.py:1279} INFO - 
--------------------------------------------------------------------------------
[2024-04-10T12:45:50.463+0000] {taskinstance.py:1280} INFO - Starting attempt 1 of 1
[2024-04-10T12:45:50.463+0000] {taskinstance.py:1281} INFO - 
--------------------------------------------------------------------------------
[2024-04-10T12:45:50.507+0000] {taskinstance.py:1300} INFO - Executing <Task(BashOperator): task2> on 2024-04-10 12:45:39.090136+00:00
[2024-04-10T12:45:50.517+0000] {standard_task_runner.py:55} INFO - Started process 2377 to run task
[2024-04-10T12:45:50.523+0000] {standard_task_runner.py:82} INFO - Running: ['***', 'tasks', 'run', 'primeira_dag', 'task2', 'manual__2024-04-10T12:45:39.090136+00:00', '--job-id', '57', '--raw', '--subdir', 'DAGS_FOLDER/teste2.py', '--cfg-path', '/tmp/tmp3l5j0soc']
[2024-04-10T12:45:50.524+0000] {standard_task_runner.py:83} INFO - Job 57: Subtask task2
[2024-04-10T12:45:50.698+0000] {task_command.py:388} INFO - Running <TaskInstance: primeira_dag.task2 manual__2024-04-10T12:45:39.090136+00:00 [running]> on host 62ba7480f9ee
[2024-04-10T12:45:50.898+0000] {taskinstance.py:1509} INFO - Exporting the following env vars:
AIRFLOW_CTX_DAG_OWNER=***
AIRFLOW_CTX_DAG_ID=primeira_dag
AIRFLOW_CTX_TASK_ID=task2
AIRFLOW_CTX_EXECUTION_DATE=2024-04-10T12:45:39.090136+00:00
AIRFLOW_CTX_TRY_NUMBER=1
AIRFLOW_CTX_DAG_RUN_ID=manual__2024-04-10T12:45:39.090136+00:00
[2024-04-10T12:45:50.900+0000] {subprocess.py:63} INFO - Tmp dir root location: 
 /tmp
[2024-04-10T12:45:50.901+0000] {subprocess.py:75} INFO - Running command: ['/bin/bash', '-c', None]
[2024-04-10T12:45:50.903+0000] {taskinstance.py:1768} ERROR - Task failed with exception
Traceback (most recent call last):
  File "/home/airflow/.local/lib/python3.7/site-packages/airflow/operators/bash.py", line 191, in execute
    cwd=self.cwd,
  File "/home/airflow/.local/lib/python3.7/site-packages/airflow/hooks/subprocess.py", line 83, in run_command
    preexec_fn=pre_exec,
  File "/usr/local/lib/python3.7/subprocess.py", line 800, in __init__
    restore_signals, start_new_session)
  File "/usr/local/lib/python3.7/subprocess.py", line 1482, in _execute_child
    restore_signals, start_new_session, preexec_fn)
TypeError: expected str, bytes or os.PathLike object, not NoneType
[2024-04-10T12:45:50.923+0000] {taskinstance.py:1323} INFO - Marking task as FAILED. dag_id=primeira_dag, task_id=task2, execution_date=20240410T124539, start_date=20240410T124550, end_date=20240410T124550
[2024-04-10T12:45:50.967+0000] {standard_task_runner.py:105} ERROR - Failed to execute job 57 for task task2 (expected str, bytes or os.PathLike object, not NoneType; 2377)
[2024-04-10T12:45:51.020+0000] {local_task_job.py:208} INFO - Task exited with return code 1
[2024-04-10T12:45:51.106+0000] {taskinstance.py:2578} INFO - 0 downstream tasks scheduled from follow-on schedule check
